[2023-12-27 17:59:46,324] {taskinstance.py:1179} INFO - Dependencies all met for <TaskInstance: OpenWeather_ETL2.envio_mail manual__2023-12-27T17:54:20.503605+00:00 [queued]>
[2023-12-27 17:59:46,350] {taskinstance.py:1179} INFO - Dependencies all met for <TaskInstance: OpenWeather_ETL2.envio_mail manual__2023-12-27T17:54:20.503605+00:00 [queued]>
[2023-12-27 17:59:46,351] {taskinstance.py:1376} INFO - 
--------------------------------------------------------------------------------
[2023-12-27 17:59:46,353] {taskinstance.py:1377} INFO - Starting attempt 2 of 6
[2023-12-27 17:59:46,354] {taskinstance.py:1378} INFO - 
--------------------------------------------------------------------------------
[2023-12-27 17:59:46,394] {taskinstance.py:1397} INFO - Executing <Task(PythonOperator): envio_mail> on 2023-12-27 17:54:20.503605+00:00
[2023-12-27 17:59:46,405] {standard_task_runner.py:52} INFO - Started process 13400 to run task
[2023-12-27 17:59:46,416] {standard_task_runner.py:79} INFO - Running: ['***', 'tasks', 'run', 'OpenWeather_ETL2', 'envio_mail', 'manual__2023-12-27T17:54:20.503605+00:00', '--job-id', '102', '--raw', '--subdir', 'DAGS_FOLDER/ETL_OpenWeather2.py', '--cfg-path', '/tmp/tmpbtnpouto', '--error-file', '/tmp/tmp__ng8yu5']
[2023-12-27 17:59:46,420] {standard_task_runner.py:80} INFO - Job 102: Subtask envio_mail
[2023-12-27 17:59:46,574] {task_command.py:371} INFO - Running <TaskInstance: OpenWeather_ETL2.envio_mail manual__2023-12-27T17:54:20.503605+00:00 [running]> on host 44a36bef83ad
[2023-12-27 17:59:46,730] {taskinstance.py:1591} INFO - Exporting the following env vars:
AIRFLOW_CTX_DAG_OWNER=Furtado_Julio
AIRFLOW_CTX_DAG_ID=OpenWeather_ETL2
AIRFLOW_CTX_TASK_ID=envio_mail
AIRFLOW_CTX_EXECUTION_DATE=2023-12-27T17:54:20.503605+00:00
AIRFLOW_CTX_TRY_NUMBER=2
AIRFLOW_CTX_DAG_RUN_ID=manual__2023-12-27T17:54:20.503605+00:00
[2023-12-27 17:59:46,753] {logging_mixin.py:115} INFO - None
[2023-12-27 17:59:46,754] {taskinstance.py:1909} ERROR - Task failed with exception
Traceback (most recent call last):
  File "/home/airflow/.local/lib/python3.7/site-packages/airflow/operators/python.py", line 171, in execute
    return_value = self.execute_callable()
  File "/home/airflow/.local/lib/python3.7/site-packages/airflow/operators/python.py", line 189, in execute_callable
    return self.python_callable(*self.op_args, **self.op_kwargs)
  File "/opt/airflow/dags/ETL_OpenWeather2.py", line 202, in envio_mail
    if threshold < 30:
TypeError: '<' not supported between instances of 'NoneType' and 'int'
[2023-12-27 17:59:46,779] {taskinstance.py:1420} INFO - Marking task as UP_FOR_RETRY. dag_id=OpenWeather_ETL2, task_id=envio_mail, execution_date=20231227T175420, start_date=20231227T175946, end_date=20231227T175946
[2023-12-27 17:59:46,800] {standard_task_runner.py:97} ERROR - Failed to execute job 102 for task envio_mail ('<' not supported between instances of 'NoneType' and 'int'; 13400)
[2023-12-27 17:59:46,827] {local_task_job.py:156} INFO - Task exited with return code 1
[2023-12-27 17:59:46,917] {local_task_job.py:273} INFO - 0 downstream tasks scheduled from follow-on schedule check
