[2023-12-27 15:50:26,678] {taskinstance.py:1179} INFO - Dependencies all met for <TaskInstance: OpenWeather_ETL2.envio_mail manual__2023-12-27T15:50:00.342705+00:00 [queued]>
[2023-12-27 15:50:26,709] {taskinstance.py:1179} INFO - Dependencies all met for <TaskInstance: OpenWeather_ETL2.envio_mail manual__2023-12-27T15:50:00.342705+00:00 [queued]>
[2023-12-27 15:50:26,710] {taskinstance.py:1376} INFO - 
--------------------------------------------------------------------------------
[2023-12-27 15:50:26,711] {taskinstance.py:1377} INFO - Starting attempt 1 of 6
[2023-12-27 15:50:26,712] {taskinstance.py:1378} INFO - 
--------------------------------------------------------------------------------
[2023-12-27 15:50:26,762] {taskinstance.py:1397} INFO - Executing <Task(PythonOperator): envio_mail> on 2023-12-27 15:50:00.342705+00:00
[2023-12-27 15:50:26,775] {standard_task_runner.py:52} INFO - Started process 4479 to run task
[2023-12-27 15:50:26,787] {standard_task_runner.py:79} INFO - Running: ['***', 'tasks', 'run', 'OpenWeather_ETL2', 'envio_mail', 'manual__2023-12-27T15:50:00.342705+00:00', '--job-id', '83', '--raw', '--subdir', 'DAGS_FOLDER/ETL_OpenWeather2.py', '--cfg-path', '/tmp/tmpp4uiek9i', '--error-file', '/tmp/tmp8n5u5abq']
[2023-12-27 15:50:26,792] {standard_task_runner.py:80} INFO - Job 83: Subtask envio_mail
[2023-12-27 15:50:26,968] {task_command.py:371} INFO - Running <TaskInstance: OpenWeather_ETL2.envio_mail manual__2023-12-27T15:50:00.342705+00:00 [running]> on host 44a36bef83ad
[2023-12-27 15:50:27,089] {logging_mixin.py:115} WARNING - /home/***/.local/lib/python3.7/site-packages/***/utils/context.py:202 AirflowContextDeprecationWarning: Accessing 'execution_date' from the template is deprecated and will be removed in a future version. Please use 'data_interval_start' or 'logical_date' instead.
[2023-12-27 15:50:27,234] {taskinstance.py:1591} INFO - Exporting the following env vars:
AIRFLOW_CTX_DAG_OWNER=Furtado_Julio
AIRFLOW_CTX_DAG_ID=OpenWeather_ETL2
AIRFLOW_CTX_TASK_ID=envio_mail
AIRFLOW_CTX_EXECUTION_DATE=2023-12-27T15:50:00.342705+00:00
AIRFLOW_CTX_TRY_NUMBER=1
AIRFLOW_CTX_DAG_RUN_ID=manual__2023-12-27T15:50:00.342705+00:00
[2023-12-27 15:50:27,245] {taskinstance.py:1909} ERROR - Task failed with exception
Traceback (most recent call last):
  File "/home/airflow/.local/lib/python3.7/site-packages/airflow/operators/python.py", line 171, in execute
    return_value = self.execute_callable()
  File "/home/airflow/.local/lib/python3.7/site-packages/airflow/operators/python.py", line 189, in execute_callable
    return self.python_callable(*self.op_args, **self.op_kwargs)
TypeError: envio_mail() takes 0 positional arguments but 1 was given
[2023-12-27 15:50:27,296] {taskinstance.py:1420} INFO - Marking task as UP_FOR_RETRY. dag_id=OpenWeather_ETL2, task_id=envio_mail, execution_date=20231227T155000, start_date=20231227T155026, end_date=20231227T155027
[2023-12-27 15:50:27,378] {standard_task_runner.py:97} ERROR - Failed to execute job 83 for task envio_mail (envio_mail() takes 0 positional arguments but 1 was given; 4479)
[2023-12-27 15:50:27,449] {local_task_job.py:156} INFO - Task exited with return code 1
[2023-12-27 15:50:27,611] {local_task_job.py:273} INFO - 0 downstream tasks scheduled from follow-on schedule check
