[2023-12-27 14:47:59,710] {taskinstance.py:1179} INFO - Dependencies all met for <TaskInstance: dag_smtp_email_fin_mundo.dag_envio_fin_mundo manual__2023-12-27T14:47:54.893057+00:00 [queued]>
[2023-12-27 14:47:59,761] {taskinstance.py:1179} INFO - Dependencies all met for <TaskInstance: dag_smtp_email_fin_mundo.dag_envio_fin_mundo manual__2023-12-27T14:47:54.893057+00:00 [queued]>
[2023-12-27 14:47:59,762] {taskinstance.py:1376} INFO - 
--------------------------------------------------------------------------------
[2023-12-27 14:47:59,763] {taskinstance.py:1377} INFO - Starting attempt 1 of 1
[2023-12-27 14:47:59,764] {taskinstance.py:1378} INFO - 
--------------------------------------------------------------------------------
[2023-12-27 14:47:59,825] {taskinstance.py:1397} INFO - Executing <Task(PythonOperator): dag_envio_fin_mundo> on 2023-12-27 14:47:54.893057+00:00
[2023-12-27 14:47:59,843] {standard_task_runner.py:52} INFO - Started process 543 to run task
[2023-12-27 14:47:59,867] {standard_task_runner.py:79} INFO - Running: ['***', 'tasks', 'run', 'dag_smtp_email_fin_mundo', 'dag_envio_fin_mundo', 'manual__2023-12-27T14:47:54.893057+00:00', '--job-id', '72', '--raw', '--subdir', 'DAGS_FOLDER/DAG_EmailTest.py', '--cfg-path', '/tmp/tmpx95pieka', '--error-file', '/tmp/tmp_d4pq99m']
[2023-12-27 14:47:59,880] {standard_task_runner.py:80} INFO - Job 72: Subtask dag_envio_fin_mundo
[2023-12-27 14:48:00,405] {task_command.py:371} INFO - Running <TaskInstance: dag_smtp_email_fin_mundo.dag_envio_fin_mundo manual__2023-12-27T14:47:54.893057+00:00 [running]> on host 44a36bef83ad
[2023-12-27 14:48:00,788] {taskinstance.py:1591} INFO - Exporting the following env vars:
AIRFLOW_CTX_DAG_OWNER=JulioFurtado
AIRFLOW_CTX_DAG_ID=dag_smtp_email_fin_mundo
AIRFLOW_CTX_TASK_ID=dag_envio_fin_mundo
AIRFLOW_CTX_EXECUTION_DATE=2023-12-27T14:47:54.893057+00:00
AIRFLOW_CTX_TRY_NUMBER=1
AIRFLOW_CTX_DAG_RUN_ID=manual__2023-12-27T14:47:54.893057+00:00
[2023-12-27 14:48:02,260] {logging_mixin.py:115} INFO - 'ascii' codec can't encode character '\xe9' in position 549: ordinal not in range(128)
[2023-12-27 14:48:02,261] {logging_mixin.py:115} INFO - Failure
[2023-12-27 14:48:02,263] {python.py:173} INFO - Done. Returned value was: None
[2023-12-27 14:48:02,319] {taskinstance.py:1420} INFO - Marking task as SUCCESS. dag_id=dag_smtp_email_fin_mundo, task_id=dag_envio_fin_mundo, execution_date=20231227T144754, start_date=20231227T144759, end_date=20231227T144802
[2023-12-27 14:48:02,401] {local_task_job.py:156} INFO - Task exited with return code 0
[2023-12-27 14:48:02,483] {local_task_job.py:273} INFO - 0 downstream tasks scheduled from follow-on schedule check
