[2023-12-27 16:19:56,058] {taskinstance.py:1179} INFO - Dependencies all met for <TaskInstance: OpenWeather_ETL2.cargar_data manual__2023-12-27T16:19:37.576458+00:00 [queued]>
[2023-12-27 16:19:56,083] {taskinstance.py:1179} INFO - Dependencies all met for <TaskInstance: OpenWeather_ETL2.cargar_data manual__2023-12-27T16:19:37.576458+00:00 [queued]>
[2023-12-27 16:19:56,084] {taskinstance.py:1376} INFO - 
--------------------------------------------------------------------------------
[2023-12-27 16:19:56,085] {taskinstance.py:1377} INFO - Starting attempt 1 of 6
[2023-12-27 16:19:56,085] {taskinstance.py:1378} INFO - 
--------------------------------------------------------------------------------
[2023-12-27 16:19:56,120] {taskinstance.py:1397} INFO - Executing <Task(PythonOperator): cargar_data> on 2023-12-27 16:19:37.576458+00:00
[2023-12-27 16:19:56,129] {standard_task_runner.py:52} INFO - Started process 7133 to run task
[2023-12-27 16:19:56,138] {standard_task_runner.py:79} INFO - Running: ['***', 'tasks', 'run', 'OpenWeather_ETL2', 'cargar_data', 'manual__2023-12-27T16:19:37.576458+00:00', '--job-id', '93', '--raw', '--subdir', 'DAGS_FOLDER/ETL_OpenWeather2.py', '--cfg-path', '/tmp/tmpo9inwfco', '--error-file', '/tmp/tmpswm85uhs']
[2023-12-27 16:19:56,141] {standard_task_runner.py:80} INFO - Job 93: Subtask cargar_data
[2023-12-27 16:19:56,300] {task_command.py:371} INFO - Running <TaskInstance: OpenWeather_ETL2.cargar_data manual__2023-12-27T16:19:37.576458+00:00 [running]> on host 44a36bef83ad
[2023-12-27 16:19:56,412] {logging_mixin.py:115} WARNING - /home/***/.local/lib/python3.7/site-packages/***/utils/context.py:202 AirflowContextDeprecationWarning: Accessing 'execution_date' from the template is deprecated and will be removed in a future version. Please use 'data_interval_start' or 'logical_date' instead.
[2023-12-27 16:19:56,520] {taskinstance.py:1591} INFO - Exporting the following env vars:
AIRFLOW_CTX_DAG_OWNER=Furtado_Julio
AIRFLOW_CTX_DAG_ID=OpenWeather_ETL2
AIRFLOW_CTX_TASK_ID=cargar_data
AIRFLOW_CTX_EXECUTION_DATE=2023-12-27T16:19:37.576458+00:00
AIRFLOW_CTX_TRY_NUMBER=1
AIRFLOW_CTX_DAG_RUN_ID=manual__2023-12-27T16:19:37.576458+00:00
[2023-12-27 16:19:56,523] {logging_mixin.py:115} INFO - Cargando la data para la fecha: 2023-12-27 16
[2023-12-27 16:19:56,558] {logging_mixin.py:115} INFO - (3, 18)
[2023-12-27 16:19:56,622] {logging_mixin.py:115} INFO -                     dt          name  ...         sunrise_time          sunset_time
0  2023-12-27 13:03:24  Buenos Aires  ...  2023-12-27 05:40:26  2023-12-27 20:08:14
1                   dt          name  ...         sunrise_time          sunset_time
2  2023-12-27 13:19:44  Buenos Aires  ...  2023-12-27 05:40:26  2023-12-27 20:08:14

[3 rows x 18 columns]
[2023-12-27 16:19:58,481] {taskinstance.py:1909} ERROR - Task failed with exception
Traceback (most recent call last):
  File "/home/airflow/.local/lib/python3.7/site-packages/airflow/operators/python.py", line 171, in execute
    return_value = self.execute_callable()
  File "/home/airflow/.local/lib/python3.7/site-packages/airflow/operators/python.py", line 189, in execute_callable
    return self.python_callable(*self.op_args, **self.op_kwargs)
  File "/opt/airflow/dags/ETL_OpenWeather2.py", line 190, in cargar_data
    execute_values(cur, insert_sql, values)
  File "/home/airflow/.local/lib/python3.7/site-packages/psycopg2/extras.py", line 1270, in execute_values
    cur.execute(b''.join(parts))
psycopg2.errors.InvalidTextRepresentation: invalid input syntax for type double precision: "longitude"

[2023-12-27 16:19:58,534] {taskinstance.py:1420} INFO - Marking task as UP_FOR_RETRY. dag_id=OpenWeather_ETL2, task_id=cargar_data, execution_date=20231227T161937, start_date=20231227T161956, end_date=20231227T161958
[2023-12-27 16:19:58,564] {standard_task_runner.py:97} ERROR - Failed to execute job 93 for task cargar_data (invalid input syntax for type double precision: "longitude"
; 7133)
[2023-12-27 16:19:58,611] {local_task_job.py:156} INFO - Task exited with return code 1
[2023-12-27 16:19:58,712] {local_task_job.py:273} INFO - 0 downstream tasks scheduled from follow-on schedule check
